<?xml version="1.0"?>
<robot xmlns:xacro="http://www.ros.org/wiki/xacro">
    <xacro:macro name="dof6bot_description"/>
    <!-- <xacro:include filename="$(find dofbot_description)/urdf/inc/create_link.xacro"/> -->

    <link name="base_link">
        <visual>
            <origin xyz="0 0 0" rpy="0 0 0" />
            <geometry>
                <mesh filename="package://dofbot_description/meshes/base_link.STL" />
            </geometry>
            <material name="">
                <color rgba="0.2 0.2 0.2 1" />
            </material>
        </visual>
        <collision>
            <origin xyz="0 0 0" rpy="0 0 0" />
            <geometry>
                <mesh filename="package://dofbot_description/meshes/base_link.STL" />
            </geometry>
        </collision>
    </link>
    
    <link name="arm_link1">
        <inertial>
            <origin xyz="1.99179507982521E-05 -5.98354652829568E-05 0.0114289358828097" rpy="0 0 0" />
            <mass value="0.0279545499871709" />
            <inertia ixx="1.19144359314975E-05" ixy="-9.26068510046816E-09" ixz="3.16060516198683E-09" iyy="1.05642517915377E-05" iyz="2.69674403668579E-08" izz="1.49639510661413E-05" />
        </inertial>
        <visual>
            <origin xyz="0 0 0" rpy="0 0 0" />
            <geometry>
                <mesh filename="package://dofbot_description/meshes/visual/arm_link1.STL" />
            </geometry>
            <material name="">
                <color rgba="1 1 1 1" />
            </material>
        </visual>
        <collision>
            <origin xyz="0 0 0" rpy="0 0 0" />
            <geometry>
                <mesh filename="package://dofbot_description/meshes/collision/arm_link1.STL" />
            </geometry>
        </collision>
    </link>
    
    <joint name="arm_joint1" type="revolute">
        <origin xyz="0 0 0.06605" rpy="-0.010805 0 1.5" />
        <parent link="base_link" />
        <child link="arm_link1" />
        <axis xyz="0 0 1" />
        <limit effort="30" velocity="1.0" lower="-1.5708" upper="1.5708" />
    </joint>
    
    
    <link name="arm_link2">
        <inertial>
            <origin xyz="0.024903 -0.0022632 -0.00066663" rpy="0 0 0" />
            <mass value="0.031605" />
            <inertia ixx="5.8495E-06" ixy="-8.8092E-07" ixz="1.5336E-07" iyy="2.667E-05" iyz="7.1365E-09" izz="2.4695E-05" />
        </inertial>
        <visual>
            <origin xyz="0 0 0" rpy="0 0 0" />
            <geometry>
                <mesh filename="package://dofbot_description/meshes/visual/arm_link2.STL" />
            </geometry>
            <material name="">
                <color rgba="1 1 1 1" />
            </material>
        </visual>
        <collision>
            <origin xyz="0 0 0" rpy="0 0 0" />
            <geometry>
                <mesh filename="package://dofbot_description/meshes/collision/arm_link2.STL" />
            </geometry>
        </collision>
    </link>
    <joint name="arm_joint2" type="revolute">
        <origin xyz="0 0 0.0405" rpy="-1.5708 0 0" />
        <parent link="arm_link1" />
        <child link="arm_link2" />
        <axis xyz="0 0 -1" />
        <limit lower="-1.5708" upper="1.5708" effort="100" velocity="1" />
    </joint>
    <link name="arm_link3">
        <inertial>
            <origin xyz="0.024903 -0.0022634 -0.0013962" rpy="0 0 0" />
            <mass value="0.031605" />
            <inertia ixx="5.8492E-06" ixy="-8.8063E-07" ixz="1.4331E-07" iyy="2.667E-05" iyz="8.9675E-09" izz="2.4695E-05" />
        </inertial>
        <visual>
            <origin xyz="0 0 0" rpy="0 0 0" />
            <geometry>
                <mesh filename="package://dofbot_description/meshes/visual/arm_link3.STL" />
            </geometry>
            <material name="">
                <color rgba="1 1 1 1.0" />
            </material>
        </visual>
        <collision>
            <origin xyz="0 0 0" rpy="0 0 0" />
            <geometry>
                <mesh filename="package://dofbot_description/meshes/collision/arm_link3.STL" />
            </geometry>
        </collision>
    </link>
    <joint name="arm_joint3" type="revolute">
        <origin xyz="0 -0.0829 0" rpy="0 0 0" />
        <parent link="arm_link2" />
        <child link="arm_link3" />
        <axis xyz="0 0 -1" />
        <limit lower="-1.5708" upper="1.5708" effort="100" velocity="1" />
    </joint>
    <link name="arm_link4">
        <inertial>
            <origin xyz="0.036246 0.0023413 -0.0019655" rpy="0 0 0" />
            <mass value="0.049766" />
            <inertia ixx="1.1857E-05" ixy="-6.5371E-06" ixz="-4.1044E-08" iyy="3.6323E-05" iyz="-1.2132E-07" izz="4.1769E-05" />
        </inertial>
        <visual>
            <origin xyz="0 0 0" rpy="0 0 0" />
            <geometry>
                <mesh filename="package://dofbot_description/meshes/visual/arm_link4.STL" />
            </geometry>
            <material name="">
                <color rgba="1 1 1 1" />
            </material>
        </visual>
        <collision>
            <origin xyz="0 0 0" rpy="0 0 0" />
            <geometry>
                <mesh filename="package://dofbot_description/meshes/collision/arm_link4.STL" />
            </geometry>
        </collision>
    </link>
    <joint name="arm_joint4" type="revolute">
        <origin xyz="0 -0.0829 0" rpy="0 0 0" />
        <parent link="arm_link3" />
        <child link="arm_link4" />
        <axis xyz="0 0 -1" />
        <limit lower="-1.5708" upper="1.5708" effort="100" velocity="1" />
    </joint>
    <link name="arm_link5">
        <inertial>
            <origin xyz="0.0023228 0.018169 0.028684" rpy="0 0 0" />
            <mass value="0.04069" />
            <inertia ixx="1.0627E-05" ixy="-3.0402E-07" ixz="-1.9524E-07" iyy="9.6306E-06" iyz="-1.3265E-06" izz="1.3298E-05" />
        </inertial>
        <visual>
            <origin xyz="0 0 0" rpy="0 0 0" />
            <geometry>
                <mesh filename="package://dofbot_description/meshes/visual/arm_link5.STL" />
            </geometry>
            <material name="">
                <color rgba="1 1 1 1" />
            </material>
        </visual>
        <collision>
            <origin xyz="0 0 0" rpy="0 0 0" />
            <geometry>
                <mesh filename="package://dofbot_description/meshes/collision/arm_link5.STL" />
            </geometry>
        </collision>
    </link>
    <joint name="arm_joint5" type="revolute">
        <origin xyz="-0.00215 -0.17455 0" rpy="1.5708 0 0" />
        <parent link="arm_link4" />
        <child link="arm_link5" />
        <axis xyz="0 0 1" />
        <limit lower="-1.5708" upper="3.14159" effort="100" velocity="1" />
    </joint>
    <link name="rlink1">
        <inertial>
            <origin xyz="0.00653227489887718 0.000416767821288678 0.000980984132845697" rpy="0 0 0" />
            <mass value="0.00117883201961805" />
            <inertia ixx="3.30415008842026E-08" ixy="8.05114594599862E-09" ixz="-1.46441757999184E-10" iyy="1.67254031134004E-07" iyz="-9.31932225400159E-12" izz="1.99277285249309E-07" />
        </inertial>
        <visual>
            <origin xyz="0 0 0" rpy="0 0 0" />
            <geometry>
                <mesh filename="package://dofbot_description/meshes/visual/rlink1.STL" />
            </geometry>
            <material name="">
                <color rgba="1 1 1 1" />
            </material>
        </visual>
        <collision>
            <origin xyz="0 0 0" rpy="0 0 0" />
            <geometry>
                <mesh filename="package://dofbot_description/meshes/visual/rlink1.STL" />
            </geometry>
        </collision>
    </link>
    <joint name="grip_joint" type="revolute">
        <origin xyz="-0.0035 -0.012625 -0.0685" rpy="0 -1.5708 0" />
        <parent link="arm_link5" />
        <child link="rlink1" />
        <axis xyz="0 0 1" />
        <limit lower="-1.54" upper="0" effort="100" velocity="1" />
    </joint>
    <link name="rlink2">
        <inertial>
            <origin xyz="0.021158 0.0063295 -0.0030251" rpy="0 0 0" />
            <mass value="0.0024469" />
            <inertia ixx="5.188E-08" ixy="-1.2303E-07" ixz="-1.2978E-09" iyy="6.3204E-07" iyz="-3.8824E-10" izz="6.6364E-07" />
        </inertial>
        <visual>
            <origin xyz="0 0 0" rpy="0 0 0" />
            <geometry>
                <mesh filename="package://dofbot_description/meshes/visual/rlink2.STL" />
            </geometry>
            <material name="">
                <color rgba="1 1 1 1" />
            </material>
        </visual>
        <collision>
            <origin xyz="0 0 0" rpy="0 0 0" />
            <geometry>
                <mesh filename="package://dofbot_description/meshes/visual/rlink2.STL" />
            </geometry>
        </collision>
    </link>
    <joint name="rlink_joint2" type="continuous">
        <origin xyz="0.03 -0.00075429 0" rpy="0 0 0" />
        <parent link="rlink1" />
        <child link="rlink2" />
        <axis xyz="0 0 1" />
        <mimic joint="grip_joint" multiplier="-1" />
    </joint>
    <link name="rlink3">
        <inertial>
            <origin xyz="0.014355 1.1499E-05 -0.0033992" rpy="0 0 0" />
            <mass value="0.00087627" />
            <inertia ixx="2.0534E-08" ixy="-1.0235E-10" ixz="1.074E-09" iyy="1.4825E-07" iyz="8.7073E-13" izz="1.3089E-07" />
        </inertial>
        <visual>
            <origin xyz="0 0 0" rpy="0 0 0" />
            <geometry>
                <mesh filename="package://dofbot_description/meshes/visual/rlink3.STL" />
            </geometry>
            <material name="">
                <color rgba="1 1 1 1" />
            </material>
        </visual>
        <collision>
            <origin xyz="0 0 0" rpy="0 0 0" />
            <geometry>
                <mesh filename="package://dofbot_description/meshes/visual/rlink3.STL" />
            </geometry>
        </collision>
    </link>
    <joint name="rlink_joint3" type="continuous">
        <origin xyz="-0.0035 -0.0045 -0.0505" rpy="0 -1.5708 0" />
        <parent link="arm_link5" />
        <child link="rlink3" />
        <axis xyz="0 0 1" />
        <mimic joint="grip_joint" multiplier="1" />
    </joint>
    <link name="llink1">
        <inertial>
            <origin xyz="0.00628617364795481 -0.000318530407893543 0.00100000338924466" rpy="0 0 0" />
            <mass value="0.00121010771282268" />
            <inertia ixx="3.18226609060835E-08" ixy="-8.06236004452728E-09" ixz="3.99064856025629E-14" iyy="1.69267681405915E-07" iyz="1.87039773440675E-14" izz="2.00283878176223E-07" />
        </inertial>
        <visual>
            <origin xyz="0 0 0" rpy="0 0 0" />
            <geometry>
                <mesh filename="package://dofbot_description/meshes/visual/llink1.STL" />
            </geometry>
            <material name="">
                <color rgba="1 1 1 1" />
            </material>
        </visual>
        <collision>
            <origin xyz="0 0 0" rpy="0 0 0" />
            <geometry>
                <mesh filename="package://dofbot_description/meshes/visual/llink1.STL" />
            </geometry>
        </collision>
    </link>
    <joint name="llink_joint1" type="continuous">
        <origin xyz="-0.0035 0.012375 -0.0685" rpy="0 -1.5708 0" />
        <parent link="arm_link5" />
        <child link="llink1" />
        <axis xyz="0 0 1" />
        <mimic joint="grip_joint" multiplier="-1" />
    </joint>
    <link name="llink2">
        <inertial>
            <origin xyz="0.021159 -0.0063248 -0.0030251" rpy="0 0 0" />
            <mass value="0.0024469" />
            <inertia ixx="5.1826E-08" ixy="1.229E-07" ixz="-1.2979E-09" iyy="6.321E-07" iyz="3.8796E-10" izz="6.6364E-07" />
        </inertial>
        <visual>
            <origin xyz="0 0 0" rpy="0 0 0" />
            <geometry>
                <mesh filename="package://dofbot_description/meshes/visual/llink2.STL" />
            </geometry>
            <material name="">
                <color rgba="1 1 1 1" />
            </material>
        </visual>
        <collision>
            <origin xyz="0 0 0" rpy="0 0 0" />
            <geometry>
                <mesh filename="package://dofbot_description/meshes/visual/llink2.STL" />
            </geometry>
        </collision>
    </link>
    <joint name="llink_joint2" type="continuous">
        <origin xyz="0.03 0.00065104 0" rpy="0 0 0" />
        <parent link="llink1" />
        <child link="llink2" />
        <axis xyz="0 0 1" />
        <mimic joint="grip_joint" multiplier="1" />
    </joint>
    <link name="llink3">
        <inertial>
            <origin xyz="0.014354 -7.4795E-05 -0.0033992" rpy="0 0 0" />
            <mass value="0.00087627" />
            <inertia ixx="2.0537E-08" ixy="6.6549E-10" ixz="1.074E-09" iyy="1.4825E-07" iyz="-5.5867E-12" izz="1.3089E-07" />
        </inertial>
        <visual>
            <origin xyz="0 0 0" rpy="0 0 0" />
            <geometry>
                <mesh filename="package://dofbot_description/meshes/visual/llink3.STL" />
            </geometry>
            <material name="">
                <color rgba="1 1 1 1" />
            </material>
        </visual>
        <collision>
            <origin xyz="0 0 0" rpy="0 0 0" />
            <geometry>
                <mesh filename="package://dofbot_description/meshes/visual/llink3.STL" />
            </geometry>
        </collision>
    </link>
    <joint name="llink_joint3" type="continuous">
        <origin xyz="-0.0035 0.0045 -0.0505" rpy="0 -1.5708 0" />
        <parent link="arm_link5" />
        <child link="llink3" />
        <axis xyz="0 0 1" />
        <mimic joint="grip_joint" multiplier="-1" />
    </joint>
 
</robot>
